<robot
  name="gemini_arm_description">
  <link
    name="base_link">
    <inertial>
      <origin
        xyz="-0.000343175586928217 0.00159787363524548 0.0403642614752203"
        rpy="0 0 0" />
      <mass
        value="0.538356341355379" />
      <inertia
        ixx="0.000222899831003167"
        ixy="3.67509961815862E-07"
        ixz="-6.55749815031895E-07"
        iyy="0.000221481349506304"
        iyz="4.21671858829881E-06"
        izz="3.91522409370845E-06" />
    </inertial>
    <visual>
      <origin
        xyz="0 0 0"
        rpy="0 0 0" />
      <geometry>
        <mesh
          filename="package://gemini_arm_description/meshes/base_link.STL" />
      </geometry>
      <material
        name="">
        <color
          rgba="0.752941176470588 0.752941176470588 0.752941176470588 1" />
      </material>
    </visual>
    <collision>
      <origin
        xyz="0 0 0"
        rpy="0 0 0" />
      <geometry>
        <mesh
          filename="package://gemini_arm_description/meshes/base_link.STL" />
      </geometry>
    </collision>
  </link>
  <link
    name="link1">
    <inertial>
      <origin
        xyz="0.00024367655569788 -0.00765546940645609 0.054816676528136"
        rpy="0 0 0" />
      <mass
        value="0.429111339765699" />
      <inertia
        ixx="0.000409405108031969"
        ixy="7.2667427177108E-06"
        ixz="-5.905713312897E-07"
        iyy="8.54561562597217E-05"
        iyz="2.90764208063669E-05"
        izz="0.000326683712310298" />
    </inertial>
    <visual>
      <origin
        xyz="0 0 0"
        rpy="0 0 0" />
      <geometry>
        <mesh
          filename="package://gemini_arm_description/meshes/link1.STL" />
      </geometry>
      <material
        name="">
        <color
          rgba="0.752941176470588 0.752941176470588 0.752941176470588 1" />
      </material>
    </visual>
    <collision>
      <origin
        xyz="0 0 0"
        rpy="0 0 0" />
      <geometry>
        <mesh
          filename="package://gemini_arm_description/meshes/link1.STL" />
      </geometry>
    </collision>
  </link>
  <joint
    name="joint1"
    type="continuous">
    <origin
      xyz="0 0 0.0919999999999988"
      rpy="0 -5.40931672317945E-57 0" />
    <parent
      link="base_link" />
    <child
      link="link1" />
    <axis
      xyz="0 0 1" />
  </joint>
  <link
    name="link2">
    <inertial>
      <origin
        xyz="-8.17473248966882E-05 0.0758952429917575 -0.00330618034524405"
        rpy="0 0 0" />
      <mass
        value="0.302188994279634" />
      <inertia
        ixx="0.0010159649861604"
        ixy="-2.93594711382165E-06"
        ixz="-2.13328310648836E-05"
        iyy="0.00086331027836668"
        iyz="-0.000118741141128118"
        izz="0.000153709642304199" />
    </inertial>
    <visual>
      <origin
        xyz="0 0 0"
        rpy="0 0 0" />
      <geometry>
        <mesh
          filename="package://gemini_arm_description/meshes/link2.STL" />
      </geometry>
      <material
        name="">
        <color
          rgba="0.752941176470588 0.752941176470588 0.752941176470588 1" />
      </material>
    </visual>
    <collision>
      <origin
        xyz="0 0 0"
        rpy="0 0 0" />
      <geometry>
        <mesh
          filename="package://gemini_arm_description/meshes/link2.STL" />
      </geometry>
    </collision>
  </link>
  <joint
    name="joint2"
    type="continuous">
    <origin
      xyz="0 0 0.060000000000028"
      rpy="1.57079632679489 4.93038065763132E-29 0" />
    <parent
      link="link1" />
    <child
      link="link2" />
    <axis
      xyz="0.0247180551164637 0 0.999694462198956" />
  </joint>
  <link
    name="link3">
    <inertial>
      <origin
        xyz="1.46872506379533E-05 0.00957042421327847 0.000512942113211096"
        rpy="0 0 0" />
      <mass
        value="0.304609228794722" />
      <inertia
        ixx="0.000242576727670286"
        ixy="2.17319668714494E-07"
        ixz="-4.7905709289069E-06"
        iyy="0.000193449162659685"
        iyz="8.79117964216302E-06"
        izz="4.93660161141823E-05" />
    </inertial>
    <visual>
      <origin
        xyz="0 0 0"
        rpy="0 0 0" />
      <geometry>
        <mesh
          filename="package://gemini_arm_description/meshes/link3.STL" />
      </geometry>
      <material
        name="">
        <color
          rgba="0.752941176470588 0.752941176470588 0.752941176470588 1" />
      </material>
    </visual>
    <collision>
      <origin
        xyz="0 0 0"
        rpy="0 0 0" />
      <geometry>
        <mesh
          filename="package://gemini_arm_description/meshes/link3.STL" />
      </geometry>
    </collision>
  </link>
  <joint
    name="joint3"
    type="continuous">
    <origin
      xyz="0 0.159999999999972 0"
      rpy="0 0 0" />
    <parent
      link="link2" />
    <child
      link="link3" />
    <axis
      xyz="0.0247180551164622 0 0.999694462198956" />
  </joint>
  <link
    name="link4">
    <inertial>
      <origin
        xyz="-0.000394301628560645 0.0159924901247282 0.105573895390213"
        rpy="0 0 0" />
      <mass
        value="0.305571705527713" />
      <inertia
        ixx="0.00159912421860763"
        ixy="1.38485660329673E-05"
        ixz="9.44824858813277E-06"
        iyy="0.00103932931783288"
        iyz="-0.000380817387210956"
        izz="0.00056047969841544" />
    </inertial>
    <visual>
      <origin
        xyz="0 0 0"
        rpy="0 0 0" />
      <geometry>
        <mesh
          filename="package://gemini_arm_description/meshes/link4.STL" />
      </geometry>
      <material
        name="">
        <color
          rgba="0.792156862745098 0.819607843137255 0.933333333333333 1" />
      </material>
    </visual>
    <collision>
      <origin
        xyz="0 0 0"
        rpy="0 0 0" />
      <geometry>
        <mesh
          filename="package://gemini_arm_description/meshes/link4.STL" />
      </geometry>
    </collision>
  </link>
  <joint
    name="joint4"
    type="continuous">
    <origin
      xyz="0 0.0600000000000281 0"
      rpy="-1.5707963267949 -9.90895775309162E-32 2.1075722764802E-16" />
    <parent
      link="link3" />
    <child
      link="link4" />
    <axis
      xyz="0 0 1" />
  </joint>
  <link
    name="link5">
    <inertial>
      <origin
        xyz="0.00114728227592453 0.0138844656415349 0.0462931681329246"
        rpy="0 0 0" />
      <mass
        value="0.109581130234744" />
      <inertia
        ixx="5.10074161279349E-05"
        ixy="-5.51294866389659E-09"
        ixz="-6.60260239698722E-07"
        iyy="2.66488845419761E-05"
        iyz="-2.54906774755437E-08"
        izz="2.43912715847687E-05" />
    </inertial>
    <visual>
      <origin
        xyz="0 0 0"
        rpy="0 0 0" />
      <geometry>
        <mesh
          filename="package://gemini_arm_description/meshes/link5.STL" />
      </geometry>
      <material
        name="">
        <color
          rgba="0.792156862745098 0.819607843137255 0.933333333333333 1" />
      </material>
    </visual>
    <collision>
      <origin
        xyz="0 0 0"
        rpy="0 0 0" />
      <geometry>
        <mesh
          filename="package://gemini_arm_description/meshes/link5.STL" />
      </geometry>
    </collision>
  </link>
  <joint
    name="joint5"
    type="continuous">
    <origin
      xyz="-0.00127297983849752 0.0514842648033036 0.206200000000001"
      rpy="1.5707963267949 2.1075722764802E-16 0" />
    <parent
      link="link4" />
    <child
      link="link5" />
    <axis
      xyz="0.0247180551163906 0 0.999694462198958" />
  </joint>
  <link
    name="link6">
    <inertial>
      <origin
        xyz="8.28330459778925E-17 -2.77555756156289E-17 0.00452342428327979"
        rpy="0 0 0" />
      <mass
        value="0.0205479341797186" />
      <inertia
        ixx="0"
        ixy="0"
        ixz="0"
        iyy="0"
        iyz="0"
        izz="0" />
    </inertial>
    <visual>
      <origin
        xyz="0 0 0"
        rpy="0 0 0" />
      <geometry>
        <mesh
          filename="package://gemini_arm_description/meshes/link6.STL" />
      </geometry>
      <material
        name="">
        <color
          rgba="0.792156862745098 0.819607843137255 0.933333333333333 1" />
      </material>
    </visual>
    <collision>
      <origin
        xyz="0 0 0"
        rpy="0 0 0" />
      <geometry>
        <mesh
          filename="package://gemini_arm_description/meshes/link6.STL" />
      </geometry>
    </collision>
  </link>
  <joint
    name="joint6"
    type="continuous">
    <origin
      xyz="0.00128533886605591 0.0461999999999435 0.0519841120344026"
      rpy="-1.5707963267949 -6.70540576712656E-29 -5.88614294757338E-14" />
    <parent
      link="link5" />
    <child
      link="link6" />
    <axis
      xyz="0 0 1" />
  </joint>
</robot>