<robot
  name="gemini_arm_description">
  <link
    name="base_link">
    <inertial>
      <origin
        xyz="-0.000958843568101282 -0.00325052357390762 0.0525293090637745"
        rpy="0 0 0" />
      <mass
        value="0.522120243745957" />
      <inertia
        ixx="0.00110754052081178"
        ixy="-3.65595856902969E-05"
        ixz="6.56884005810179E-05"
        iyy="0.000899331736125672"
        iyz="0.000395259649868102"
        izz="0.000220709036888803" />
    </inertial>
    <visual>
      <origin
        xyz="0 0 0"
        rpy="0 0 0" />
      <geometry>
        <mesh
          filename="package://gemini_arm_description/meshes/base_link.STL" />
      </geometry>
      <material
        name="">
        <color
          rgba="0.752941176470588 0.752941176470588 0.752941176470588 1" />
      </material>
    </visual>
    <collision>
      <origin
        xyz="0 0 0"
        rpy="0 0 0" />
      <geometry>
        <mesh
          filename="package://gemini_arm_description/meshes/base_link.STL" />
      </geometry>
    </collision>
  </link>
  <link
    name="link1">
    <inertial>
      <origin
        xyz="-4.39222915807336E-06 -0.00964661967877896 0.0449452594835847"
        rpy="0 0 0" />
      <mass
        value="0.407686363241537" />
      <inertia
        ixx="0.000374350414430445"
        ixy="-1.70942879919007E-08"
        ixz="8.68378269227754E-09"
        iyy="8.18333759811296E-05"
        iyz="2.78081187601253E-05"
        izz="0.000292519862490704" />
    </inertial>
    <visual>
      <origin
        xyz="0 0 0"
        rpy="0 0 0" />
      <geometry>
        <mesh
          filename="package://gemini_arm_description/meshes/link1.STL" />
      </geometry>
      <material
        name="">
        <color
          rgba="0.752941176470588 0.752941176470588 0.752941176470588 1" />
      </material>
    </visual>
    <collision>
      <origin
        xyz="0 0 0"
        rpy="0 0 0" />
      <geometry>
        <mesh
          filename="package://gemini_arm_description/meshes/link1.STL" />
      </geometry>
    </collision>
  </link>
  <joint
    name="joint1"
    type="continuous">
    <origin
      xyz="0 0 0.101999999999998"
      rpy="0 0 0" />
    <parent
      link="base_link" />
    <child
      link="link1" />
    <axis
      xyz="0 0 1" />
  </joint>
  <link
    name="link2">
    <inertial>
      <origin
        xyz="4.6019627514618E-06 0.0794970558430602 -0.00100082777526507"
        rpy="0 0 0" />
      <mass
        value="0.519627467770511" />
      <inertia
        ixx="0.00103216257260428"
        ixy="2.39320072055633E-06"
        ixz="-2.38485254898648E-10"
        iyy="0.0010294834853176"
        iyz="-0.000127015064370939"
        izz="0.00032295350690931" />
    </inertial>
    <visual>
      <origin
        xyz="0 0 0"
        rpy="0 0 0" />
      <geometry>
        <mesh
          filename="package://gemini_arm_description/meshes/link2.STL" />
      </geometry>
      <material
        name="">
        <color
          rgba="0.752941176470588 0.752941176470588 0.752941176470588 1" />
      </material>
    </visual>
    <collision>
      <origin
        xyz="0 0 0"
        rpy="0 0 0" />
      <geometry>
        <mesh
          filename="package://gemini_arm_description/meshes/link2.STL" />
      </geometry>
    </collision>
  </link>
  <joint
    name="joint2"
    type="continuous">
    <origin
      xyz="0 0 0.0499999999999997"
      rpy="1.57079632679489 0 0" />
    <parent
      link="link1" />
    <child
      link="link2" />
    <axis
      xyz="0 0 1" />
  </joint>
  <link
    name="link3">
    <inertial>
      <origin
        xyz="7.0167077895894E-07 0.00956864128740062 0.000513166719836141"
        rpy="0 0 0" />
      <mass
        value="0.304597711973766" />
      <inertia
        ixx="0.000242669760456699"
        ixy="1.89698516737036E-08"
        ixz="-1.0583413370264E-08"
        iyy="0.000193449166292588"
        iyz="8.79357915060968E-06"
        izz="4.9221651183088E-05" />
    </inertial>
    <visual>
      <origin
        xyz="0 0 0"
        rpy="0 0 0" />
      <geometry>
        <mesh
          filename="package://gemini_arm_description/meshes/link3.STL" />
      </geometry>
      <material
        name="">
        <color
          rgba="0.752941176470588 0.752941176470588 0.752941176470588 1" />
      </material>
    </visual>
    <collision>
      <origin
        xyz="0 0 0"
        rpy="0 0 0" />
      <geometry>
        <mesh
          filename="package://gemini_arm_description/meshes/link3.STL" />
      </geometry>
    </collision>
  </link>
  <joint
    name="joint3"
    type="continuous">
    <origin
      xyz="0 0.16 0"
      rpy="0 0 0" />
    <parent
      link="link2" />
    <child
      link="link3" />
    <axis
      xyz="0 0 1" />
  </joint>
  <link
    name="link4">
    <inertial>
      <origin
        xyz="0.0458867898459498 -0.0436310151927849 -0.200456202441409"
        rpy="0 0 0" />
      <mass
        value="0.354329700218231" />
      <inertia
        ixx="0.000949043504338393"
        ixy="3.51983499953334E-06"
        ixz="-1.01860842667646E-05"
        iyy="0.000585939683948872"
        iyz="-0.00018047837877197"
        izz="0.000414621919012565" />
    </inertial>
    <visual>
      <origin
        xyz="0 0 0"
        rpy="0 0 0" />
      <geometry>
        <mesh
          filename="package://gemini_arm_description/meshes/link4.STL" />
      </geometry>
      <material
        name="">
        <color
          rgba="0.752941176470588 0.752941176470588 0.752941176470588 1" />
      </material>
    </visual>
    <collision>
      <origin
        xyz="0 0 0"
        rpy="0 0 0" />
      <geometry>
        <mesh
          filename="package://gemini_arm_description/meshes/link4.STL" />
      </geometry>
    </collision>
  </link>
  <joint
    name="joint4"
    type="continuous">
    <origin
      xyz="0.0468673533334532 -0.063489360827598 -0.0297539470834349"
      rpy="-1.5707963267949 0 -3.14159265358979" />
    <parent
      link="link3" />
    <child
      link="link4" />
    <axis
      xyz="0 0 -1" />
  </joint>
  <link
    name="link5">
    <inertial>
      <origin
        xyz="-2.65538255195263E-06 -0.0138830300674611 0.0463123217063122"
        rpy="0 0 0" />
      <mass
        value="0.109559148486022" />
      <inertia
        ixx="5.10012496222163E-05"
        ixy="-4.88164896235126E-09"
        ixz="1.75233694653623E-09"
        iyy="2.6624271637639E-05"
        iyz="2.85957622723357E-08"
        izz="2.43769805164704E-05" />
    </inertial>
    <visual>
      <origin
        xyz="0 0 0"
        rpy="0 0 0" />
      <geometry>
        <mesh
          filename="package://gemini_arm_description/meshes/link5.STL" />
      </geometry>
      <material
        name="">
        <color
          rgba="0.792156862745098 0.819607843137255 0.933333333333333 1" />
      </material>
    </visual>
    <collision>
      <origin
        xyz="0 0 0"
        rpy="0 0 0" />
      <geometry>
        <mesh
          filename="package://gemini_arm_description/meshes/link5.STL" />
      </geometry>
    </collision>
  </link>
  <joint
    name="joint5"
    type="continuous">
    <origin
      xyz="0.0468673533334465 -0.0817539470834755 -0.289689360827598"
      rpy="1.5707963267949 -1.83186799063149E-15 -3.14159265358979" />
    <parent
      link="link4" />
    <child
      link="link5" />
    <axis
      xyz="0 0 -1" />
  </joint>
  <link
    name="link6">
    <inertial>
      <origin
        xyz="1.08370626587737E-05 5.34594741623956E-07 0.0121432868076762"
        rpy="0 0 0" />
      <mass
        value="0.0278364815211388" />
      <inertia
        ixx="0"
        ixy="0"
        ixz="0"
        iyy="0"
        iyz="0"
        izz="0" />
    </inertial>
    <visual>
      <origin
        xyz="0 0 0"
        rpy="0 0 0" />
      <geometry>
        <mesh
          filename="package://gemini_arm_description/meshes/link6.STL" />
      </geometry>
      <material
        name="">
        <color
          rgba="0.792156862745098 0.819607843137255 0.933333333333333 1" />
      </material>
    </visual>
    <collision>
      <origin
        xyz="0 0 0"
        rpy="0 0 0" />
      <geometry>
        <mesh
          filename="package://gemini_arm_description/meshes/link6.STL" />
      </geometry>
    </collision>
  </link>
  <joint
    name="joint6"
    type="continuous">
    <origin
      xyz="0 -0.0457 0.052"
      rpy="1.5707963267949 -3.18770542568412E-16 -2.2904450444239E-15" />
    <parent
      link="link5" />
    <child
      link="link6" />
    <axis
      xyz="0 0 1" />
  </joint>
</robot>