<robot
  name="gemini_arm_description">
  <link
    name="base_link">
    <inertial>
      <origin
        xyz="-0.000958843568101282 -0.00325052357390763 0.0525293090637745"
        rpy="0 0 0" />
      <mass
        value="0.522120243745957" />
      <inertia
        ixx="0.00110754052081178"
        ixy="-3.65595856902969E-05"
        ixz="6.56884005810179E-05"
        iyy="0.000899331736125672"
        iyz="0.000395259649868102"
        izz="0.000220709036888803" />
    </inertial>
    <visual>
      <origin
        xyz="0 0 0"
        rpy="0 0 0" />
      <geometry>
        <mesh
          filename="package://gemini_arm_description/meshes/base_link.STL" />
      </geometry>
      <material
        name="">
        <color
          rgba="0.752941176470588 0.752941176470588 0.752941176470588 1" />
      </material>
    </visual>
    <collision>
      <origin
        xyz="0 0 0"
        rpy="0 0 0" />
      <geometry>
        <mesh
          filename="package://gemini_arm_description/meshes/base_link.STL" />
      </geometry>
    </collision>
  </link>
  <link
    name="link1">
    <inertial>
      <origin
        xyz="-4.39222915803172E-06 -0.00964661967877896 0.0449452594835846"
        rpy="0 0 0" />
      <mass
        value="0.407686363241537" />
      <inertia
        ixx="0.000374350414430445"
        ixy="-1.70942879918529E-08"
        ixz="8.68378269222623E-09"
        iyy="8.18333759811297E-05"
        iyz="2.78081187601253E-05"
        izz="0.000292519862490704" />
    </inertial>
    <visual>
      <origin
        xyz="0 0 0"
        rpy="0 0 0" />
      <geometry>
        <mesh
          filename="package://gemini_arm_description/meshes/link1.STL" />
      </geometry>
      <material
        name="">
        <color
          rgba="0.752941176470588 0.752941176470588 0.752941176470588 1" />
      </material>
    </visual>
    <collision>
      <origin
        xyz="0 0 0"
        rpy="0 0 0" />
      <geometry>
        <mesh
          filename="package://gemini_arm_description/meshes/link1.STL" />
      </geometry>
    </collision>
  </link>
  <joint
    name="joint1"
    type="continuous">
    <origin
      xyz="0 0 0.101999999999998"
      rpy="0 0 0" />
    <parent
      link="base_link" />
    <child
      link="link1" />
    <axis
      xyz="0 0 1" />
  </joint>
  <link
    name="link2">
    <inertial>
      <origin
        xyz="4.60196275140629E-06 0.0794970558430598 -0.00100082777526737"
        rpy="0 0 0" />
      <mass
        value="0.519627467770511" />
      <inertia
        ixx="0.00103216257260436"
        ixy="2.39320072055007E-06"
        ixz="-2.38485258600182E-10"
        iyy="0.00102948348531767"
        iyz="-0.000127015064370948"
        izz="0.00032295350690931" />
    </inertial>
    <visual>
      <origin
        xyz="0 0 0"
        rpy="0 0 0" />
      <geometry>
        <mesh
          filename="package://gemini_arm_description/meshes/link2.STL" />
      </geometry>
      <material
        name="">
        <color
          rgba="0.752941176470588 0.752941176470588 0.752941176470588 1" />
      </material>
    </visual>
    <collision>
      <origin
        xyz="0 0 0"
        rpy="0 0 0" />
      <geometry>
        <mesh
          filename="package://gemini_arm_description/meshes/link2.STL" />
      </geometry>
    </collision>
  </link>
  <joint
    name="joint2"
    type="continuous">
    <origin
      xyz="0 0 0.0499999999999997"
      rpy="1.57079632679489 0 0" />
    <parent
      link="link1" />
    <child
      link="link2" />
    <axis
      xyz="0 0 1" />
  </joint>
  <link
    name="link3">
    <inertial>
      <origin
        xyz="7.01670779236496E-07 0.00956864128487746 0.000513166719837713"
        rpy="0 0 0" />
      <mass
        value="0.304597711973767" />
      <inertia
        ixx="0.000242669760461465"
        ixy="1.89698516734279E-08"
        ixz="-1.05834133682735E-08"
        iyy="0.000193449166292586"
        iyz="8.79357913176038E-06"
        izz="4.92216511878556E-05" />
    </inertial>
    <visual>
      <origin
        xyz="0 0 0"
        rpy="0 0 0" />
      <geometry>
        <mesh
          filename="package://gemini_arm_description/meshes/link3.STL" />
      </geometry>
      <material
        name="">
        <color
          rgba="0.752941176470588 0.752941176470588 0.752941176470588 1" />
      </material>
    </visual>
    <collision>
      <origin
        xyz="0 0 0"
        rpy="0 0 0" />
      <geometry>
        <mesh
          filename="package://gemini_arm_description/meshes/link3.STL" />
      </geometry>
    </collision>
  </link>
  <joint
    name="joint3"
    type="continuous">
    <origin
      xyz="0 0.16 0"
      rpy="0 0 0" />
    <parent
      link="link2" />
    <child
      link="link3" />
    <axis
      xyz="0 0 1" />
  </joint>
  <link
    name="link4">
    <inertial>
      <origin
        xyz="-0.00112685377453307 0.0156487385025263 0.0833718629087101"
        rpy="0 0 0" />
      <mass
        value="0.305449608651427" />
      <inertia
        ixx="0.000837561682940551"
        ixy="-4.09825922317542E-06"
        ixz="8.07368933470307E-06"
        iyy="0.000481550336920109"
        iyz="-0.000153767703143327"
        izz="0.000407434312990563" />
    </inertial>
    <visual>
      <origin
        xyz="0 0 0"
        rpy="0 0 0" />
      <geometry>
        <mesh
          filename="package://gemini_arm_description/meshes/link4.STL" />
      </geometry>
      <material
        name="">
        <color
          rgba="0.792156862745098 0.819607843137255 0.933333333333333 1" />
      </material>
    </visual>
    <collision>
      <origin
        xyz="0 0 0"
        rpy="0 0 0" />
      <geometry>
        <mesh
          filename="package://gemini_arm_description/meshes/link4.STL" />
      </geometry>
    </collision>
  </link>
  <joint
    name="joint4"
    type="continuous">
    <origin
      xyz="0 0.06 0"
      rpy="-1.5707963267949 0 0" />
    <parent
      link="link3" />
    <child
      link="link4" />
    <axis
      xyz="0 0 1" />
  </joint>
  <link
    name="link5">
    <inertial>
      <origin
        xyz="2.65538254819869E-06 0.0138830300674618 0.0463123217063128"
        rpy="0 0 0" />
      <mass
        value="0.109559148486021" />
      <inertia
        ixx="5.10012496222164E-05"
        ixy="-4.88164896226459E-09"
        ixz="-1.75233694461864E-09"
        iyy="2.6624271637639E-05"
        iyz="-2.85957622724453E-08"
        izz="2.43769805164704E-05" />
    </inertial>
    <visual>
      <origin
        xyz="0 0 0"
        rpy="0 0 0" />
      <geometry>
        <mesh
          filename="package://gemini_arm_description/meshes/link5.STL" />
      </geometry>
      <material
        name="">
        <color
          rgba="0.792156862745098 0.819607843137255 0.933333333333333 1" />
      </material>
    </visual>
    <collision>
      <origin
        xyz="0 0 0"
        rpy="0 0 0" />
      <geometry>
        <mesh
          filename="package://gemini_arm_description/meshes/link5.STL" />
      </geometry>
    </collision>
  </link>
  <joint
    name="joint5"
    type="continuous">
    <origin
      xyz="0 0.0520000000000001 0.1662"
      rpy="1.5707963267949 0 0" />
    <parent
      link="link4" />
    <child
      link="link5" />
    <axis
      xyz="0 0 1" />
  </joint>
  <link
    name="link6">
    <inertial>
      <origin
        xyz="-1.0837062659183E-05 -5.3459474222417E-07 0.0116432868077339"
        rpy="0 0 0" />
      <mass
        value="0.0278364815211388" />
      <inertia
        ixx="0"
        ixy="0"
        ixz="0"
        iyy="0"
        iyz="0"
        izz="0" />
    </inertial>
    <visual>
      <origin
        xyz="0 0 0"
        rpy="0 0 0" />
      <geometry>
        <mesh
          filename="package://gemini_arm_description/meshes/link6.STL" />
      </geometry>
      <material
        name="">
        <color
          rgba="0.792156862745098 0.819607843137255 0.933333333333333 1" />
      </material>
    </visual>
    <collision>
      <origin
        xyz="0 0 0"
        rpy="0 0 0" />
      <geometry>
        <mesh
          filename="package://gemini_arm_description/meshes/link6.STL" />
      </geometry>
    </collision>
  </link>
  <joint
    name="joint6"
    type="continuous">
    <origin
      xyz="0 0.046199999999943 0.052"
      rpy="-1.5707963267949 1.55872001956863E-31 1.50753608972822E-15" />
    <parent
      link="link5" />
    <child
      link="link6" />
    <axis
      xyz="0 0 1" />
  </joint>
</robot>