<robot
  name="gemini_arm_description">
  <link
    name="base_link">
    <inertial>
      <origin
        xyz="-0.000958843568101275 -0.00325052357390762 0.0525293090637745"
        rpy="0 0 0" />
      <mass
        value="0.522120243745957" />
      <inertia
        ixx="0.00110754052081178"
        ixy="-3.65595856902969E-05"
        ixz="6.56884005810179E-05"
        iyy="0.000899331736125673"
        iyz="0.000395259649868102"
        izz="0.000220709036888803" />
    </inertial>
    <visual>
      <origin
        xyz="0 0 0"
        rpy="0 0 0" />
      <geometry>
        <mesh
          filename="package://gemini_arm_description/meshes/base_link.STL" />
      </geometry>
      <material
        name="">
        <color
          rgba="0.752941176470588 0.752941176470588 0.752941176470588 1" />
      </material>
    </visual>
    <collision>
      <origin
        xyz="0 0 0"
        rpy="0 0 0" />
      <geometry>
        <mesh
          filename="package://gemini_arm_description/meshes/base_link.STL" />
      </geometry>
    </collision>
  </link>
  <link
    name="link1">
    <inertial>
      <origin
        xyz="-4.39222915803866E-06 -0.00964661967877897 0.0449452594835846"
        rpy="0 0 0" />
      <mass
        value="0.407686363241537" />
      <inertia
        ixx="0.000374350414430445"
        ixy="-1.70942879918695E-08"
        ixz="8.68378269227291E-09"
        iyy="8.18333759811297E-05"
        iyz="2.78081187601253E-05"
        izz="0.000292519862490704" />
    </inertial>
    <visual>
      <origin
        xyz="0 0 0"
        rpy="0 0 0" />
      <geometry>
        <mesh
          filename="package://gemini_arm_description/meshes/link1.STL" />
      </geometry>
      <material
        name="">
        <color
          rgba="0.752941176470588 0.752941176470588 0.752941176470588 1" />
      </material>
    </visual>
    <collision>
      <origin
        xyz="0 0 0"
        rpy="0 0 0" />
      <geometry>
        <mesh
          filename="package://gemini_arm_description/meshes/link1.STL" />
      </geometry>
    </collision>
  </link>
  <joint
    name="joint1"
    type="continuous">
    <origin
      xyz="0 0 0.101999999999998"
      rpy="0 0 0" />
    <parent
      link="base_link" />
    <child
      link="link1" />
    <axis
      xyz="0 0 1" />
  </joint>
  <link
    name="link2">
    <inertial>
      <origin
        xyz="4.60205152059273E-06 0.0794971457990815 -0.000999834386867824"
        rpy="0 0 0" />
      <mass
        value="0.519617444659105" />
      <inertia
        ixx="0.00103207189078498"
        ixy="2.39320093566873E-06"
        ixz="-2.36109758946631E-10"
        iyy="0.00102945690186196"
        iyz="-0.000127012657113227"
        izz="0.000322889408545222" />
    </inertial>
    <visual>
      <origin
        xyz="0 0 0"
        rpy="0 0 0" />
      <geometry>
        <mesh
          filename="package://gemini_arm_description/meshes/link2.STL" />
      </geometry>
      <material
        name="">
        <color
          rgba="0.792156862745098 0.819607843137255 0.933333333333333 1" />
      </material>
    </visual>
    <collision>
      <origin
        xyz="0 0 0"
        rpy="0 0 0" />
      <geometry>
        <mesh
          filename="package://gemini_arm_description/meshes/link2.STL" />
      </geometry>
    </collision>
  </link>
  <joint
    name="joint2"
    type="continuous">
    <origin
      xyz="0 0 0.0499999999999997"
      rpy="1.57079632679489 0 0" />
    <parent
      link="link1" />
    <child
      link="link2" />
    <axis
      xyz="0 0 1" />
  </joint>
  <link
    name="link3">
    <inertial>
      <origin
        xyz="7.01670779229557E-07 0.00956864128487744 0.000513166719837699"
        rpy="0 0 0" />
      <mass
        value="0.304597711973767" />
      <inertia
        ixx="0.000242669760461465"
        ixy="1.89698516734279E-08"
        ixz="-1.05834133682557E-08"
        iyy="0.000193449166292586"
        iyz="8.79357913176042E-06"
        izz="4.92216511878555E-05" />
    </inertial>
    <visual>
      <origin
        xyz="0 0 0"
        rpy="0 0 0" />
      <geometry>
        <mesh
          filename="package://gemini_arm_description/meshes/link3.STL" />
      </geometry>
      <material
        name="">
        <color
          rgba="0.752941176470588 0.752941176470588 0.752941176470588 1" />
      </material>
    </visual>
    <collision>
      <origin
        xyz="0 0 0"
        rpy="0 0 0" />
      <geometry>
        <mesh
          filename="package://gemini_arm_description/meshes/link3.STL" />
      </geometry>
    </collision>
  </link>
  <joint
    name="joint3"
    type="continuous">
    <origin
      xyz="0 0.16 0"
      rpy="0 0 0" />
    <parent
      link="link2" />
    <child
      link="link3" />
    <axis
      xyz="0 0 1" />
  </joint>
  <link
    name="link4">
    <inertial>
      <origin
        xyz="0.045740482264188 -0.0454034629326281 -0.20685995250676"
        rpy="0 0 0" />
      <mass
        value="0.305444920744369" />
      <inertia
        ixx="0.000837517495011438"
        ixy="4.09852678356137E-06"
        ixz="-8.07412688816651E-06"
        iyy="0.000481518169085959"
        iyz="-0.000153787369874655"
        izz="0.000407422280990013" />
    </inertial>
    <visual>
      <origin
        xyz="0 0 0"
        rpy="0 0 0" />
      <geometry>
        <mesh
          filename="package://gemini_arm_description/meshes/link4.STL" />
      </geometry>
      <material
        name="">
        <color
          rgba="0.792156862745098 0.819607843137255 0.933333333333333 1" />
      </material>
    </visual>
    <collision>
      <origin
        xyz="0 0 0"
        rpy="0 0 0" />
      <geometry>
        <mesh
          filename="package://gemini_arm_description/meshes/link4.STL" />
      </geometry>
    </collision>
  </link>
  <joint
    name="joint4"
    type="continuous">
    <origin
      xyz="0.0468673533334532 -0.063489360827598 -0.0297539470834349"
      rpy="-1.5707963267949 0 -3.14159265358979" />
    <parent
      link="link3" />
    <child
      link="link4" />
    <axis
      xyz="0 0 -1" />
  </joint>
  <link
    name="link5">
    <inertial>
      <origin
        xyz="-2.65538255159181E-06 -0.0138830300674618 0.0463123217063128"
        rpy="0 0 0" />
      <mass
        value="0.109559148486021" />
      <inertia
        ixx="5.10012496222163E-05"
        ixy="-4.88164896236596E-09"
        ixz="1.75233694653432E-09"
        iyy="2.66242716376389E-05"
        iyz="2.85957622723679E-08"
        izz="2.43769805164704E-05" />
    </inertial>
    <visual>
      <origin
        xyz="0 0 0"
        rpy="0 0 0" />
      <geometry>
        <mesh
          filename="package://gemini_arm_description/meshes/link5.STL" />
      </geometry>
      <material
        name="">
        <color
          rgba="0.792156862745098 0.819607843137255 0.933333333333333 1" />
      </material>
    </visual>
    <collision>
      <origin
        xyz="0 0 0"
        rpy="0 0 0" />
      <geometry>
        <mesh
          filename="package://gemini_arm_description/meshes/link5.STL" />
      </geometry>
    </collision>
  </link>
  <joint
    name="joint5"
    type="continuous">
    <origin
      xyz="0.0468673533334465 -0.0817539470834755 -0.289689360827598"
      rpy="1.5707963267949 -1.83186799063149E-15 -3.14159265358979" />
    <parent
      link="link4" />
    <child
      link="link5" />
    <axis
      xyz="0 0 -1" />
  </joint>
  <link
    name="link6">
    <inertial>
      <origin
        xyz="1.08370626591275E-05 5.34594742203354E-07 0.012143286807677"
        rpy="0 0 0" />
      <mass
        value="0.0278364815211388" />
      <inertia
        ixx="0"
        ixy="0"
        ixz="0"
        iyy="0"
        iyz="0"
        izz="0" />
    </inertial>
    <visual>
      <origin
        xyz="0 0 0"
        rpy="0 0 0" />
      <geometry>
        <mesh
          filename="package://gemini_arm_description/meshes/link6.STL" />
      </geometry>
      <material
        name="">
        <color
          rgba="0.792156862745098 0.819607843137255 0.933333333333333 1" />
      </material>
    </visual>
    <collision>
      <origin
        xyz="0 0 0"
        rpy="0 0 0" />
      <geometry>
        <mesh
          filename="package://gemini_arm_description/meshes/link6.STL" />
      </geometry>
    </collision>
  </link>
  <joint
    name="joint6"
    type="continuous">
    <origin
      xyz="0 -0.0457 0.052"
      rpy="1.5707963267949 -3.18770542568412E-16 -2.2904450444239E-15" />
    <parent
      link="link5" />
    <child
      link="link6" />
    <axis
      xyz="0 0 1" />
  </joint>
</robot>